Workbook

Sheet README
B2: FMVA Prep — Practice Modeling Workbook
B4: Companion to the 7-day FMVA certification prep bootcamp (Lesson Forge Pro · Investment vertical).
B5: All company data is FICTIONAL ("Falcon Manufacturing Co.") and illustrative for teaching only.
B6: Independent study material. FMVA® is a certification of the Corporate Finance Institute (CFI);
B7: this workbook is not affiliated with, or endorsed by, CFI.
B9: How to use: work the sheets in day order. In the PRACTICE workbook, yellow cells are yours
B10: to complete (each has a comment telling you what to build). Check against the ANSWER KEY.
B12: Color code: BLUE = hardcoded input · BLACK = formula · GREEN = link to another sheet.
B14: Sheet map: Assumptions (Day 1-2) · Model = 3-statement (Day 2) · DCF (Day 3) ·
B15: Sensitivity (Day 4) · Comps (Day 5).

Sheet Assumptions
B2: Operating & valuation assumptions — Falcon Manufacturing Co. ($mm)
A4: Operating
A5: Revenue growth (yoy) | B5: 0.08 | C5: Source: illustrative teaching assumption, Lesson Forge FMVA bootcamp, 2026
A6: COGS (% of revenue) | B6: 0.6
A7: SG&A (% of revenue) | B7: 0.2
A8: D&A (% of revenue) | B8: 0.05
A9: Tax rate | B9: 0.25
A10: Capex (% of revenue) | B10: 0.06
A11: DSO (days sales outstanding) | B11: 45
A12: DIO (days inventory) | B12: 60
A13: DPO (days payables) | B13: 40
A14: Debt repayment / yr ($mm) | B14: 5
A15: Interest rate on debt | B15: 0.08
A18: Valuation (WACC build)
A19: Risk-free rate | B19: 0.045
A20: Equity risk premium | B20: 0.055
A21: Beta | B21: 1.2
A22: Cost of debt (pre-tax) | B22: 0.06
A23: Equity / total capital | B23: 0.7
A24: Debt / total capital | B24: 0.3
A25: Terminal growth (g) | B25: 0.025
A26: Diluted shares out (mm) | B26: 50
A28: Cost of equity (CAPM) | B28: =B19+B21*B20
A29: WACC | B29: =B23*B28+B24*B22*(1-B9)

Sheet Model
A1: Falcon Manufacturing Co. — integrated 3-statement model ($mm)
B3: FY2024A | C3: FY2025E | D3: FY2026E | E3: FY2027E | F3: FY2028E | G3: FY2029E
A4: Income statement
A5: Revenue | B5: 500 | C5: =B5*(1+Assumptions!$B$5) | D5: =C5*(1+Assumptions!$B$5) | E5: =D5*(1+Assumptions!$B$5) | F5: =E5*(1+Assumptions!$B$5) | G5: =F5*(1+Assumptions!$B$5)
A6: COGS | B6: 300 | C6: =C5*Assumptions!$B$6 | D6: =D5*Assumptions!$B$6 | E6: =E5*Assumptions!$B$6 | F6: =F5*Assumptions!$B$6 | G6: =G5*Assumptions!$B$6
A7: Gross profit | B7: =B5-B6 | C7: =C5-C6 | D7: =D5-D6 | E7: =E5-E6 | F7: =F5-F6 | G7: =G5-G6
A8: SG&A | B8: 100 | C8: =C5*Assumptions!$B$7 | D8: =D5*Assumptions!$B$7 | E8: =E5*Assumptions!$B$7 | F8: =F5*Assumptions!$B$7 | G8: =G5*Assumptions!$B$7
A9: EBITDA | B9: =B7-B8 | C9: =C7-C8 | D9: =D7-D8 | E9: =E7-E8 | F9: =F7-F8 | G9: =G7-G8
A10: D&A | B10: 25 | C10: =C5*Assumptions!$B$8 | D10: =D5*Assumptions!$B$8 | E10: =E5*Assumptions!$B$8 | F10: =F5*Assumptions!$B$8 | G10: =G5*Assumptions!$B$8
A11: EBIT | B11: =B9-B10 | C11: =C9-C10 | D11: =D9-D10 | E11: =E9-E10 | F11: =F9-F10 | G11: =G9-G10
A12: Interest expense | B12: 8 | C12: =B38*Assumptions!$B$15 | D12: =C38*Assumptions!$B$15 | E12: =D38*Assumptions!$B$15 | F12: =E38*Assumptions!$B$15 | G12: =F38*Assumptions!$B$15
A13: Pre-tax income | B13: =B11-B12 | C13: =C11-C12 | D13: =D11-D12 | E13: =E11-E12 | F13: =F11-F12 | G13: =G11-G12
A14: Taxes | B14: =B13*Assumptions!$B$9 | C14: =C13*Assumptions!$B$9 | D14: =D13*Assumptions!$B$9 | E14: =E13*Assumptions!$B$9 | F14: =F13*Assumptions!$B$9 | G14: =G13*Assumptions!$B$9
A15: Net income | B15: =B13-B14 | C15: =C13-C14 | D15: =D13-D14 | E15: =E13-E14 | F15: =F13-F14 | G15: =G13-G14
A17: Working capital
A18: Accounts receivable | B18: =B5/365*Assumptions!$B$11 | C18: =C5/365*Assumptions!$B$11 | D18: =D5/365*Assumptions!$B$11 | E18: =E5/365*Assumptions!$B$11 | F18: =F5/365*Assumptions!$B$11 | G18: =G5/365*Assumptions!$B$11
A19: Inventory | B19: =B6/365*Assumptions!$B$12 | C19: =C6/365*Assumptions!$B$12 | D19: =D6/365*Assumptions!$B$12 | E19: =E6/365*Assumptions!$B$12 | F19: =F6/365*Assumptions!$B$12 | G19: =G6/365*Assumptions!$B$12
A20: Accounts payable | B20: =B6/365*Assumptions!$B$13 | C20: =C6/365*Assumptions!$B$13 | D20: =D6/365*Assumptions!$B$13 | E20: =E6/365*Assumptions!$B$13 | F20: =F6/365*Assumptions!$B$13 | G20: =G6/365*Assumptions!$B$13
A21: Net working capital | B21: =B18+B19-B20 | C21: =C18+C19-C20 | D21: =D18+D19-D20 | E21: =E18+E19-E20 | F21: =F18+F19-F20 | G21: =G18+G19-G20
A22: Change in NWC | B22: 0 | C22: =C21-B21 | D22: =D21-C21 | E22: =E21-D21 | F22: =F21-E21 | G22: =G21-F21
A24: Cash flow statement
A25: Net income | C25: =C15 | D25: =D15 | E25: =E15 | F25: =F15 | G25: =G15
A26: (+) D&A | C26: =C10 | D26: =D10 | E26: =E10 | F26: =F10 | G26: =G10
A27: (−) Change in NWC | C27: =-C22 | D27: =-D22 | E27: =-E22 | F27: =-F22 | G27: =-G22
A28: Cash from operations | C28: =SUM(C25:C27) | D28: =SUM(D25:D27) | E28: =SUM(E25:E27) | F28: =SUM(F25:F27) | G28: =SUM(G25:G27)
A29: Capex | C29: =-C5*Assumptions!$B$10 | D29: =-D5*Assumptions!$B$10 | E29: =-E5*Assumptions!$B$10 | F29: =-F5*Assumptions!$B$10 | G29: =-G5*Assumptions!$B$10
A30: Debt repayment | C30: =-Assumptions!$B$14 | D30: =-Assumptions!$B$14 | E30: =-Assumptions!$B$14 | F30: =-Assumptions!$B$14 | G30: =-Assumptions!$B$14
A31: Net change in cash | C31: =C28+C29+C30 | D31: =D28+D29+D30 | E31: =E28+E29+E30 | F31: =F28+F29+F30 | G31: =G28+G29+G30
A32: Ending cash | B32: 40 | C32: =B32+C31 | D32: =C32+D31 | E32: =D32+E31 | F32: =E32+F31 | G32: =F32+G31
A34: Balance sheet (year end)
A35: Cash | B35: =B32 | C35: =C32 | D35: =D32 | E35: =E32 | F35: =F32 | G35: =G32
A36: Accounts receivable | B36: =B18 | C36: =C18 | D36: =D18 | E36: =E18 | F36: =F18 | G36: =G18
A37: Inventory | B37: =B19 | C37: =C19 | D37: =D19 | E37: =E19 | F37: =F19 | G37: =G19
A38: Debt (opening, memo) | B38: 100 | C38: =B42 | D38: =C42 | E38: =D42 | F38: =E42 | G38: =F42
A39: PP&E, net | B39: 200 | C39: =B39+C5*Assumptions!$B$10-C10 | D39: =C39+D5*Assumptions!$B$10-D10 | E39: =D39+E5*Assumptions!$B$10-E10 | F39: =E39+F5*Assumptions!$B$10-F10 | G39: =F39+G5*Assumptions!$B$10-G10
A40: Total assets | B40: =B35+B36+B37+B39 | C40: =C35+C36+C37+C39 | D40: =D35+D36+D37+D39 | E40: =E35+E36+E37+E39 | F40: =F35+F36+F37+F39 | G40: =G35+G36+G37+G39
A41: Accounts payable | B41: =B20 | C41: =C20 | D41: =D20 | E41: =E20 | F41: =F20 | G41: =G20
A42: Debt | B42: =B38 | C42: =B42-Assumptions!$B$14 | D42: =C42-Assumptions!$B$14 | E42: =D42-Assumptions!$B$14 | F42: =E42-Assumptions!$B$14 | G42: =F42-Assumptions!$B$14
A43: Shareholders' equity | B43: =B40-B41-B42 | C43: =B43+C15 | D43: =C43+D15 | E43: =D43+E15 | F43: =E43+F15 | G43: =F43+G15
A44: Total liabilities & equity | B44: =B41+B42+B43 | C44: =C41+C42+C43 | D44: =D41+D42+D43 | E44: =E41+E42+E43 | F44: =F41+F42+F43 | G44: =G41+G42+G43
...

Sheet DCF
A1: Discounted cash flow valuation ($mm except per share)
C3: FY2025E | D3: FY2026E | E3: FY2027E | F3: FY2028E | G3: FY2029E
A4: Period (t) | C4: 1 | D4: 2 | E4: 3 | F4: 4 | G4: 5
A5: Unlevered FCF | C5: =Model!C11*(1-Assumptions!$B$9)+Model!C10-Model!C5*Assumptions!$B$10-Model!C22 | D5: =Model!D11*(1-Assumptions!$B$9)+Model!D10-Model!D5*Assumptions!$B$10-Model!D22 | E5: =Model!E11*(1-Assumptions!$B$9)+Model!E10-Model!E5*Assumptions!$B$10-Model!E22 | F5: =Model!F11*(1-Assumptions!$B$9)+Model!F10-Model!F5*Assumptions!$B$10-Model!F22 | G5: =Model!G11*(1-Assumptions!$B$9)+Model!G10-Model!G5*Assumptions!$B$10-Model!G22
A6: Discount factor | C6: =1/(1+$B$10)^C4 | D6: =1/(1+$B$10)^D4 | E6: =1/(1+$B$10)^E4 | F6: =1/(1+$B$10)^F4 | G6: =1/(1+$B$10)^G4
A7: PV of FCF | C7: =C5*C6 | D7: =D5*D6 | E7: =E5*E6 | F7: =F5*F6 | G7: =G5*G6
A10: WACC | B10: =Assumptions!B29
A11: Terminal growth (g) | B11: =Assumptions!B25
A12: Diluted shares (mm) | B12: =Assumptions!B26
A14: Sum of PV (2025–29) | B14: =SUM(C7:G7)
A15: Terminal value (Gordon) | B15: =G5*(1+B11)/(B10-B11)
A16: PV of terminal value | B16: =B15*G6
A17: Enterprise value | B17: =B14+B16
A18: Less: net debt (2024) | B18: =Model!B42-Model!B35
A19: Equity value | B19: =B17-B18
A20: Implied value per share ($) | B20: =B19/B12

Sheet Sensitivity
A1: Value per share ($) — WACC × terminal growth
A2: Rows: WACC · Columns: terminal g. Uses the same FCFs as the DCF sheet.
B4: 0.015 | C4: 0.02 | D4: 0.025 | E4: 0.03 | F4: 0.035
A5: 0.085 | B5: =(SUMPRODUCT(DCF!$C$5:$G$5,1/(1+$A5)^$B$13:$F$13)+DCF!$G$5*(1+B$4)/($A5-B$4)/(1+$A5)^5-(Model!$B$42-Model!$B$35))/DCF!$B$12 | C5: =(SUMPRODUCT(DCF!$C$5:$G$5,1/(1+$A5)^$B$13:$F$13)+DCF!$G$5*(1+C$4)/($A5-C$4)/(1+$A5)^5-(Model!$B$42-Model!$B$35))/DCF!$B$12 | D5: =(SUMPRODUCT(DCF!$C$5:$G$5,1/(1+$A5)^$B$13:$F$13)+DCF!$G$5*(1+D$4)/($A5-D$4)/(1+$A5)^5-(Model!$B$42-Model!$B$35))/DCF!$B$12 | E5: =(SUMPRODUCT(DCF!$C$5:$G$5,1/(1+$A5)^$B$13:$F$13)+DCF!$G$5*(1+E$4)/($A5-E$4)/(1+$A5)^5-(Model!$B$42-Model!$B$35))/DCF!$B$12 | F5: =(SUMPRODUCT(DCF!$C$5:$G$5,1/(1+$A5)^$B$13:$F$13)+DCF!$G$5*(1+F$4)/($A5-F$4)/(1+$A5)^5-(Model!$B$42-Model!$B$35))/DCF!$B$12
A6: 0.09 | B6: =(SUMPRODUCT(DCF!$C$5:$G$5,1/(1+$A6)^$B$13:$F$13)+DCF!$G$5*(1+B$4)/($A6-B$4)/(1+$A6)^5-(Model!$B$42-Model!$B$35))/DCF!$B$12 | C6: =(SUMPRODUCT(DCF!$C$5:$G$5,1/(1+$A6)^$B$13:$F$13)+DCF!$G$5*(1+C$4)/($A6-C$4)/(1+$A6)^5-(Model!$B$42-Model!$B$35))/DCF!$B$12 | D6: =(SUMPRODUCT(DCF!$C$5:$G$5,1/(1+$A6)^$B$13:$F$13)+DCF!$G$5*(1+D$4)/($A6-D$4)/(1+$A6)^5-(Model!$B$42-Model!$B$35))/DCF!$B$12 | E6: =(SUMPRODUCT(DCF!$C$5:$G$5,1/(1+$A6)^$B$13:$F$13)+DCF!$G$5*(1+E$4)/($A6-E$4)/(1+$A6)^5-(Model!$B$42-Model!$B$35))/DCF!$B$12 | F6: =(SUMPRODUCT(DCF!$C$5:$G$5,1/(1+$A6)^$B$13:$F$13)+DCF!$G$5*(1+F$4)/($A6-F$4)/(1+$A6)^5-(Model!$B$42-Model!$B$35))/DCF!$B$12
A7: 0.095 | B7: =(SUMPRODUCT(DCF!$C$5:$G$5,1/(1+$A7)^$B$13:$F$13)+DCF!$G$5*(1+B$4)/($A7-B$4)/(1+$A7)^5-(Model!$B$42-Model!$B$35))/DCF!$B$12 | C7: =(SUMPRODUCT(DCF!$C$5:$G$5,1/(1+$A7)^$B$13:$F$13)+DCF!$G$5*(1+C$4)/($A7-C$4)/(1+$A7)^5-(Model!$B$42-Model!$B$35))/DCF!$B$12 | D7: =(SUMPRODUCT(DCF!$C$5:$G$5,1/(1+$A7)^$B$13:$F$13)+DCF!$G$5*(1+D$4)/($A7-D$4)/(1+$A7)^5-(Model!$B$42-Model!$B$35))/DCF!$B$12 | E7: =(SUMPRODUCT(DCF!$C$5:$G$5,1/(1+$A7)^$B$13:$F$13)+DCF!$G$5*(1+E$4)/($A7-E$4)/(1+$A7)^5-(Model!$B$42-Model!$B$35))/DCF!$B$12 | F7: =(SUMPRODUCT(DCF!$C$5:$G$5,1/(1+$A7)^$B$13:$F$13)+DCF!$G$5*(1+F$4)/($A7-F$4)/(1+$A7)^5-(Model!$B$42-Model!$B$35))/DCF!$B$12
A8: 0.1 | B8: =(SUMPRODUCT(DCF!$C$5:$G$5,1/(1+$A8)^$B$13:$F$13)+DCF!$G$5*(1+B$4)/($A8-B$4)/(1+$A8)^5-(Model!$B$42-Model!$B$35))/DCF!$B$12 | C8: =(SUMPRODUCT(DCF!$C$5:$G$5,1/(1+$A8)^$B$13:$F$13)+DCF!$G$5*(1+C$4)/($A8-C$4)/(1+$A8)^5-(Model!$B$42-Model!$B$35))/DCF!$B$12 | D8: =(SUMPRODUCT(DCF!$C$5:$G$5,1/(1+$A8)^$B$13:$F$13)+DCF!$G$5*(1+D$4)/($A8-D$4)/(1+$A8)^5-(Model!$B$42-Model!$B$35))/DCF!$B$12 | E8: =(SUMPRODUCT(DCF!$C$5:$G$5,1/(1+$A8)^$B$13:$F$13)+DCF!$G$5*(1+E$4)/($A8-E$4)/(1+$A8)^5-(Model!$B$42-Model!$B$35))/DCF!$B$12 | F8: =(SUMPRODUCT(DCF!$C$5:$G$5,1/(1+$A8)^$B$13:$F$13)+DCF!$G$5*(1+F$4)/($A8-F$4)/(1+$A8)^5-(Model!$B$42-Model!$B$35))/DCF!$B$12
A9: 0.105 | B9: =(SUMPRODUCT(DCF!$C$5:$G$5,1/(1+$A9)^$B$13:$F$13)+DCF!$G$5*(1+B$4)/($A9-B$4)/(1+$A9)^5-(Model!$B$42-Model!$B$35))/DCF!$B$12 | C9: =(SUMPRODUCT(DCF!$C$5:$G$5,1/(1+$A9)^$B$13:$F$13)+DCF!$G$5*(1+C$4)/($A9-C$4)/(1+$A9)^5-(Model!$B$42-Model!$B$35))/DCF!$B$12 | D9: =(SUMPRODUCT(DCF!$C$5:$G$5,1/(1+$A9)^$B$13:$F$13)+DCF!$G$5*(1+D$4)/($A9-D$4)/(1+$A9)^5-(Model!$B$42-Model!$B$35))/DCF!$B$12 | E9: =(SUMPRODUCT(DCF!$C$5:$G$5,1/(1+$A9)^$B$13:$F$13)+DCF!$G$5*(1+E$4)/($A9-E$4)/(1+$A9)^5-(Model!$B$42-Model!$B$35))/DCF!$B$12 | F9: =(SUMPRODUCT(DCF!$C$5:$G$5,1/(1+$A9)^$B$13:$F$13)+DCF!$G$5*(1+F$4)/($A9-F$4)/(1+$A9)^5-(Model!$B$42-Model!$B$35))/DCF!$B$12
A13: Periods (helper) | B13: 1 | C13: 2 | D13: 3 | E13: 4 | F13: 5

Sheet Comps
A1: Comparable companies analysis ($mm except per share)
A3: Peer (fictional) | B3: EV / EBITDA (2025E)
A4: Oryx Industrial | B4: 8.2
A5: Dune Fabrication | B5: 9.1
A6: Gulf Components | B6: 7.6
A7: Sadu Manufacturing | B7: 8.8
A8: Nakhla Engineering | B8: 9.5
A10: Median multiple | B10: =MEDIAN(B4:B8)
A12: Falcon EBITDA 2025E | B12: =Model!C9
A13: Implied enterprise value | B13: =B10*B12
A14: Less: net debt (2024) | B14: =Model!B42-Model!B35
A15: Implied equity value | B15: =B13-B14
A16: Implied value per share ($) | B16: =B15/DCF!B12
A18: DCF value per share ($) | B18: =DCF!B20
A19: Comps premium / (discount) vs DCF | B19: =B16/B18-1
